Workbook
Name bb: Patient_Data!$K$2:$K$41
Name Bills: Patient_Data!$K$2:$K$41
Name dd: Patient_Data!$E$1:$E$41
Name Department: Patient_Data!$E$2:$E$41

Sheet Patient_Data
A1: Patient_ID | B1: Patient_Name | C1: Age | D1: Gender | E1: Department | F1: Diagnosis | G1: Admission_Date | H1: Discharge_Date | I1: Doctor | J1: Insurance_Type | K1: Bill_Amount | L1: Payment_Status | M1: Length_of_Stay | N1: payment alert | O1: bill | P1: age | Q1: high billing case | S1: bill amount category | V1: urgent payment follow-up
A2: P1001 | B2: Aarav Sharma | C2: 34 | D2: Male | E2: Cardiology | F2: Hypertension | G2: 46027 | H2: 46030 | I2: Dr Rao | J2: Private Insurance | K2: 18500 | L2: Paid | M2: 3 | N2: =IF(Patient_Data!L2="pending","followup","no action") -> no action | O2: =IF(Patient_Data!K2>40000,"hb","lb") -> lb | P2: =IF(C2>=60,"sr ce","not") -> not | Q2: =AND(K2>40000,M2>5) -> FALSE | R2: =IF(AND(K2>40000,L2="pending"),"hfr","norm") -> norm | S2: =IF(K2>=50000,"Very High",IF(K2>=30000,"High",IF(K2>=15000,"Medium","Low"))) -> Medium
A3: P1002 | B3: Diya Patel | C3: 52 | D3: Female | E3: Orthopedics | F3: Fracture | G3: 46029 | H3: 46037 | I3: Dr Mehta | J3: Government | K3: 42000 | L3: Paid | M3: 8 | N3: =IF(Patient_Data!L3="pending","followup","no action") -> no action | O3: =IF(Patient_Data!K3>40000,"hb","lb") -> hb | P3: =IF(C3>=60,"sr ce","not") -> not | Q3: =AND(K3>40000,M3>5) -> TRUE | R3: =IF(AND(Patient_Data!K3>40000,Patient_Data!L3="pending"),"hfr","norm") -> norm | S3: =IF(K3>=50000,"Very High",IF(K3>=30000,"High",IF(K3>=15000,"Medium","Low"))) -> High
A4: P1003 | B4: Rohan Kumar | C4: 28 | D4: Male | E4: General Medicine | F4: Diabetes | G4: 46032 | H4: 46035 | I4: Dr Singh | J4: Private Insurance | K4: 12000 | L4: Paid | M4: 3 | N4: =IF(Patient_Data!L4="pending","followup","no action") -> no action | O4: =IF(Patient_Data!K4>40000,"hb","lb") -> lb | P4: =IF(C4>=60,"sr ce","not") -> not | Q4: =AND(K4>40000,M4>5) -> FALSE | R4: =IF(AND(Patient_Data!K4>40000,Patient_Data!L4="pending"),"hfr","norm") -> norm | S4: =IF(K4>=50000,"Very High",IF(K4>=30000,"High",IF(K4>=15000,"Medium","Low"))) -> Low
A5: P1004 | B5: Ananya Reddy | C5: 45 | D5: Female | E5: Cardiology | F5: Chest Pain | G5: 46034 | H5: 46039 | I5: Dr Rao | J5: Self Pay | K5: 27500 | L5: Pending | M5: 5 | N5: =IF(Patient_Data!L5="pending","followup","no action") -> followup | O5: =IF(Patient_Data!K5>40000,"hb","lb") -> lb | P5: =IF(C5>=60,"sr ce","not") -> not | Q5: =AND(K5>40000,M5>5) -> FALSE | R5: =IF(AND(Patient_Data!K5>40000,Patient_Data!L5="pending"),"hfr","norm") -> norm | S5: =IF(K5>=50000,"Very High",IF(K5>=30000,"High",IF(K5>=15000,"Medium","Low"))) -> Medium
A6: P1005 | B6: Vikram Singh | C6: 67 | D6: Male | E6: Neurology | F6: Migraine | G6: 46037 | H6: 46040 | I6: Dr Khan | J6: Government | K6: 16000 | L6: Paid | M6: 3 | O6: =IF(Patient_Data!K6>40000,"hb","lb") -> lb | P6: =IF(C6>=60,"sr ce","not") -> sr ce | Q6: =AND(K6>40000,M6>5) -> FALSE | R6: =IF(AND(Patient_Data!K6>40000,Patient_Data!L6="pending"),"hfr","norm") -> norm | S6: =IF(K6>=50000,"Very High",IF(K6>=30000,"High",IF(K6>=15000,"Medium","Low"))) -> Medium
A7: P1006 | B7: Meera Nair | C7: 39 | D7: Female | E7: General Medicine | F7: Asthma | G7: 46040 | H7: 46042 | I7: Dr Singh | J7: Private Insurance | K7: 9500 | L7: Paid | M7: 2 | O7: =IF(Patient_Data!K7>40000,"hb","lb") -> lb | P7: =IF(C7>=60,"sr ce","not") -> not | Q7: =AND(K7>40000,M7>5) -> FALSE | R7: =IF(AND(Patient_Data!K7>40000,Patient_Data!L7="pending"),"hfr","norm") -> norm | S7: =IF(K7>=50000,"Very High",IF(K7>=30000,"High",IF(K7>=15000,"Medium","Low"))) -> Low
A8: P1007 | B8: Arjun Verma | C8: 73 | D8: Male | E8: Cardiology | F8: Heart Disease | G8: 46042 | H8: 46051 | I8: Dr Rao | J8: Government | K8: 68000 | L8: Pending | M8: 9 | O8: =IF(Patient_Data!K8>40000,"hb","lb") -> hb | P8: =IF(C8>=60,"sr ce","not") -> sr ce | Q8: =AND(K8>40000,M8>5) -> TRUE | R8: =IF(AND(Patient_Data!K8>40000,Patient_Data!L8="pending"),"hfr","norm") -> hfr | S8: =IF(K8>=50000,"Very High",IF(K8>=30000,"High",IF(K8>=15000,"Medium","Low"))) -> Very High
A9: P1008 | B9: Sneha Iyer | C9: 31 | D9: Female | E9: Dermatology | F9: Skin Allergy | G9: 46044 | H9: 46046 | I9: Dr Thomas | J9: Self Pay | K9: 7500 | L9: Paid | M9: 2 | O9: =IF(Patient_Data!K9>40000,"hb","lb") -> lb | P9: =IF(C9>=60,"sr ce","not") -> not | Q9: =AND(K9>40000,M9>5) -> FALSE | R9: =IF(AND(Patient_Data!K9>40000,Patient_Data!L9="pending"),"hfr","norm") -> norm | S9: =IF(K9>=50000,"Very High",IF(K9>=30000,"High",IF(K9>=15000,"Medium","Low"))) -> Low
A10: P1009 | B10: Karan Shah | C10: 56 | D10: Male | E10: Orthopedics | F10: Arthritis | G10: 46047 | H10: 46052 | I10: Dr Mehta | J10: Private Insurance | K10: 24000 | L10: Paid | M10: 5 | O10: =IF(Patient_Data!K10>40000,"hb","lb") -> lb | P10: =IF(C10>=60,"sr ce","not") -> not | Q10: =AND(K10>40000,M10>5) -> FALSE | R10: =IF(AND(Patient_Data!K10>40000,Patient_Data!L10="pending"),"hfr","norm") -> norm | S10: =IF(K10>=50000,"Very High",IF(K10>=30000,"High",IF(K10>=15000,"Medium","Low"))) -> Medium
A11: P1010 | B11: Priya Das | C11: 24 | D11: Female | E11: General Medicine | F11: Fever | G11: 46050 | H11: 46052 | I11: Dr Singh | J11: Self Pay | K11: 6500 | L11: Paid | M11: 2 | O11: =IF(Patient_Data!K11>40000,"hb","lb") -> lb | P11: =IF(C11>=60,"sr ce","not") -> not | Q11: =AND(K11>40000,M11>5) -> FALSE | S11: =IF(K11>=50000,"Very High",IF(K11>=30000,"High",IF(K11>=15000,"Medium","Low"))) -> Low
A12: P1011 | B12: Aditya Rao | C12: 61 | D12: Male | E12: Cardiology | F12: Hypertension | G12: 46055 | H12: 46059 | I12: Dr Rao | J12: Private Insurance | K12: 22000 | L12: Paid | M12: 4 | O12: =IF(Patient_Data!K12>40000,"hb","lb") -> lb | P12: =IF(C12>=60,"sr ce","not") -> sr ce | S12: =IF(K12>=50000,"Very High",IF(K12>=30000,"High",IF(K12>=15000,"Medium","Low"))) -> Medium
A13: P1012 | B13: Kavya Menon | C13: 48 | D13: Female | E13: Neurology | F13: Seizure Disorder | G13: 46057 | H13: 46064 | I13: Dr Khan | J13: Government | K13: 39000 | L13: Pending | M13: 7 | O13: =IF(Patient_Data!K13>40000,"hb","lb") -> lb | P13: =IF(C13>=60,"sr ce","not") -> not | S13: =IF(K13>=50000,"Very High",IF(K13>=30000,"High",IF(K13>=15000,"Medium","Low"))) -> High
A14: P1013 | B14: Raj Malhotra | C14: 36 | D14: Male | E14: Orthopedics | F14: Back Pain | G14: 46059 | H14: 46062 | I14: Dr Mehta | J14: Self Pay | K14: 14500 | L14: Paid | M14: 3 | O14: =IF(Patient_Data!K14>40000,"hb","lb") -> lb | P14: =IF(C14>=60,"sr ce","not") -> not | S14: =IF(K14>=50000,"Very High",IF(K14>=30000,"High",IF(K14>=15000,"Medium","Low"))) -> Low
A15: P1014 | B15: Ishita Gupta | C15: 42 | D15: Female | E15: Dermatology | F15: Psoriasis | G15: 46061 | H15: 46065 | I15: Dr Thomas | J15: Private Insurance | K15: 18000 | L15: Paid | M15: 4 | O15: =IF(Patient_Data!K15>40000,"hb","lb") -> lb | P15: =IF(C15>=60,"sr ce","not") -> not | S15: =IF(K15>=50000,"Very High",IF(K15>=30000,"High",IF(K15>=15000,"Medium","Low"))) -> Medium
A16: P1015 | B16: Manish Yadav | C16: 69 | D16: Male | E16: Cardiology | F16: Heart Disease | G16: 46063 | H16: 46073 | I16: Dr Rao | J16: Government | K16: 72000 | L16: Pending | M16: 10 | O16: =IF(Patient_Data!K16>40000,"hb","lb") -> hb | S16: =IF(K16>=50000,"Very High",IF(K16>=30000,"High",IF(K16>=15000,"Medium","Low"))) -> Very High
A17: P1016 | B17: Neha Joshi | C17: 29 | D17: Female | E17: General Medicine | F17: Diabetes | G17: 46065 | H17: 46068 | I17: Dr Singh | J17: Self Pay | K17: 10500 | L17: Paid | M17: 3 | O17: =IF(Patient_Data!K17>40000,"hb","lb") -> lb | S17: =IF(K17>=50000,"Very High",IF(K17>=30000,"High",IF(K17>=15000,"Medium","Low"))) -> Low
A18: P1017 | B18: Rahul Bose | C18: 58 | D18: Male | E18: Neurology | F18: Migraine | G18: 46068 | H18: 46071 | I18: Dr Khan | J18: Private Insurance | K18: 17500 | L18: Paid | M18: 3 | O18: =IF(Patient_Data!K18>40000,"hb","lb") -> lb | S18: =IF(K18>=50000,"Very High",IF(K18>=30000,"High",IF(K18>=15000,"Medium","Low"))) -> Medium
A19: P1018 | B19: Simran Kaur | C19: 33 | D19: Female | E19: Orthopedics | F19: Fracture | G19: 46070 | H19: 46078 | I19: Dr Mehta | J19: Government | K19: 45000 | L19: Paid | M19: 8 | O19: =IF(Patient_Data!K19>40000,"hb","lb") -> hb
A20: P1019 | B20: Varun Kapoor | C20: 47 | D20: Male | E20: Dermatology | F20: Skin Allergy | G20: 46073 | H20: 46075 | I20: Dr Thomas | J20: Self Pay | K20: 8000 | L20: Pending | M20: 2 | O20: =IF(Patient_Data!K20>40000,"hb","lb") -> lb
A21: P1020 | B21: Pooja Agarwal | C21: 55 | D21: Female | E21: Cardiology | F21: Chest Pain | G21: 46075 | H21: 46080 | I21: Dr Rao | J21: Private Insurance | K21: 31000 | L21: Paid | M21: 5 | O21: =IF(Patient_Data!K21>40000,"hb","lb") -> lb
A22: P1021 | B22: Harsh Jain | C22: 40 | D22: Male | E22: General Medicine | F22: Asthma | G22: 46082 | H22: 46085 | I22: Dr Singh | J22: Government | K22: 13000 | L22: Paid | M22: 3 | O22: =IF(Patient_Data!K22>40000,"hb","lb") -> lb
A23: P1022 | B23: Nandini Rao | C23: 63 | D23: Female | E23: Neurology | F23: Seizure Disorder | G23: 46084 | H23: 46093 | I23: Dr Khan | J23: Private Insurance | K23: 48000 | L23: Paid | M23: 9 | O23: =IF(Patient_Data!K23>40000,"hb","lb") -> hb
A24: P1023 | B24: Siddharth Roy | C24: 27 | D24: Male | E24: Orthopedics | F24: Back Pain | G24: 46086 | H24: 46089 | I24: Dr Mehta | J24: Self Pay | K24: 12500 | L24: Paid | M24: 3 | O24: =IF(Patient_Data!K24>40000,"hb","lb") -> lb
A25: P1024 | B25: Shreya Kapoor | C25: 51 | D25: Female | E25: Dermatology | F25: Psoriasis | G25: 46088 | H25: 46091 | I25: Dr Thomas | J25: Government | K25: 15500 | L25: Pending | M25: 3 | O25: =IF(Patient_Data!K25>40000,"hb","lb") -> lb
A26: P1025 | B26: Abhishek Das | C26: 70 | D26: Male | E26: Cardiology | F26: Heart Disease | G26: 46091 | H26: 46102 | I26: Dr Rao | J26: Government | K26: 76000 | L26: Paid | M26: 11 | O26: =IF(Patient_Data!K26>40000,"hb","lb") -> hb
A27: P1026 | B27: Anjali Shah | C27: 37 | D27: Female | E27: General Medicine | F27: Fever | G27: 46093 | H27: 46095 | I27: Dr Singh | J27: Self Pay | K27: 6200 | L27: Paid | M27: 2 | O27: =IF(Patient_Data!K27>40000,"hb","lb") -> lb
A28: P1027 | B28: Mohit Verma | C28: 44 | D28: Male | E28: Orthopedics | F28: Arthritis | G28: 46096 | H28: 46101 | I28: Dr Mehta | J28: Private Insurance | K28: 26000 | L28: Pending | M28: 5 | O28: =IF(Patient_Data!K28>40000,"hb","lb") -> lb
A29: P1028 | B29: Riya Menon | C29: 30 | D29: Female | E29: Neurology | F29: Migraine | G29: 46098 | H29: 46100 | I29: Dr Khan | J29: Self Pay | K29: 9000 | L29: Paid | M29: 2 | O29: =IF(Patient_Data!K29>40000,"hb","lb") -> lb
A30: P1029 | B30: Deepak Nair | C30: 59 | D30: Male | E30: Dermatology | F30: Skin Allergy | G30: 46101 | H30: 46104 | I30: Dr Thomas | J30: Private Insurance | K30: 11000 | L30: Paid | M30: 3 | O30: =IF(Patient_Data!K30>40000,"hb","lb") -> lb
... A41: P1040 | B41: Sonali Shah | C41: 50 | D41: Female | E41: Cardiology | F41: Heart Disease | G41: 46134 | H41: 46144 | I41: Dr Rao | J41: Private Insurance | K41: 69000 | L41: Paid | M41: 10 | O41: =IF(Patient_Data!K41>40000,"hb","lb") -> hb
L46: Dermatology
E47: Find total hospital billing. | H47: =SUM(bb) -> 1019500 | L47: Neurology
E48: Find total billing for Cardialogy department. | H48: =SUMIF(Department,E31,bb) -> 443500 | L48: Cardiology
E49: Count patients in Dermatology department. | H49: =DCOUNTA(A1:Q41,E1,J46) -> #VALUE!
E50: Find average bill by Neurology department. | H50: =AVERAGEIF(Department,E39,bb) -> 25571.429
E51: Find total billing for Government insurance. | H51: =SUMIF(J2:J41,J40,bb) -> 499500 | J51: =DAVERAGE(A2:Q41,11,K68:K69) -> #DIV/0!
E52: Count patients with Pending payments. | H52: =COUNTIF(L2:L43,L33) -> 10
E53: Find total Pending billing.
E54: Find total billing for Cardiology + Government insurance. | H54: =SUMIF(E2:E43,J33,bb) -> 0
...

Sheet Questions
A1: Question:
A2: Create a new column called Payment Alert.
A3: If Payment Status is Pending, display "Follow Up", otherwise display "No Action".
A5: Create a column called Bill Category.
A6: Bill > ₹40,000 → High Bill
A7: Otherwise → Normal Bill
A9: Create a column called Age Category.
A10: If Age is 60 or above:Senior Citizen
A11: Otherwise:Non-Senior
A13: A patient is a High Billing Case if:
A14: Bill Amount > ₹40,000
A15: AND
... A28: Payment Completed Otherwise:Payment Pending
A30: create a bill category | B30: Bill Amount | C30: Category
B31: ≥ ₹50,000 | C31: Very High
B32: ≥ ₹30,000 | C32: High
B33: ≥ ₹15,000 | C33: Medium
B34: < ₹15,000 | C34: Low
A37: If:
A38: Bill > ₹40,000
A39: AND Payment = Pending
A40: Output:High Financial Risk Otherwise:Normal
A42: A patient needs management review if:
A44: They are from Cardiology OR Orthopedics,
A45: AND their bill is greater than ₹30,000. then MR, NO Review

Sheet Answers
A1: # | B1: Analysis | C1: Function | D1: Answer
A2: 1 | B2: Total hospital billing | C2: SUM | D2: 1019500
A3: 2 | B3: Cardiology billing | C3: SUMIF | D3: 443500
A4: 2 | B4: Dermatology billing | C4: SUMIF | D4: 89500
A5: 2 | B5: General Medicine billing | C5: SUMIF | D5: 77500
A6: 2 | B6: Neurology billing | C6: SUMIF | D6: 179000
A7: 2 | B7: Orthopedics billing | C7: SUMIF | D7: 230000
A8: 3 | B8: Cardiology patients | C8: COUNTIF | D8: 10
A9: 3 | B9: Dermatology patients | C9: COUNTIF | D9: 7
A10: 3 | B10: General Medicine patients | C10: COUNTIF | D10: 8
A11: 3 | B11: Neurology patients | C11: COUNTIF | D11: 7
A12: 3 | B12: Orthopedics patients | C12: COUNTIF | D12: 8
A13: 4 | B13: Avg Cardiology bill | C13: AVERAGEIF | D13: 44350
... A28: 15 | B28: Cardiology + stay > 5 days | C28: SUMIFS | D28: 320000
A29: 16 | B29: Avg stay of Pending patients | C29: AVERAGEIF | D29: 5.8 days
A30: 17 | B30: Maximum Cardiology bill | C30: MAXIFS | D30: 76000
A31: 18 | B31: Minimum Orthopedics bill | C31: MINIFS | D31: 12500
